2020-11-28 20:30:45,430 ERROR 75625 nodejs.ClusterClientNoResponseError: client no response in 7219076ms exceeding maxIdleTime 60000ms, maybe the connection is close on other side.
    at Timeout._onTimeout (/Users/lero/Documents/My-data/BLOG/blog_service/node_modules/cluster-client/lib/leader.js:77:23)
    at listOnTimeout (internal/timers.js:549:17)
    at processTimers (internal/timers.js:492:7)
name: "ClusterClientNoResponseError"
pid: 75625
hostname: LEROLI-MB0

2020-11-28 21:43:14,703 ERROR 75625 nodejs.ClusterClientNoResponseError: client no response in 4302390ms exceeding maxIdleTime 60000ms, maybe the connection is close on other side.
    at Timeout._onTimeout (/Users/lero/Documents/My-data/BLOG/blog_service/node_modules/cluster-client/lib/leader.js:77:23)
    at listOnTimeout (internal/timers.js:549:17)
    at processTimers (internal/timers.js:492:7)
name: "ClusterClientNoResponseError"
pid: 75625
hostname: LEROLI-MB0

2020-11-28 23:51:11,094 ERROR 75625 nodejs.ClusterClientNoResponseError: client no response in 1014972ms exceeding maxIdleTime 60000ms, maybe the connection is close on other side.
    at Timeout._onTimeout (/Users/lero/Documents/My-data/BLOG/blog_service/node_modules/cluster-client/lib/leader.js:77:23)
    at listOnTimeout (internal/timers.js:549:17)
    at processTimers (internal/timers.js:492:7)
name: "ClusterClientNoResponseError"
pid: 75625
hostname: LEROLI-MB0

2020-11-29 00:04:16,141 ERROR 75625 nodejs.ClusterClientNoResponseError: client no response in 765028ms exceeding maxIdleTime 60000ms, maybe the connection is close on other side.
    at Timeout._onTimeout (/Users/lero/Documents/My-data/BLOG/blog_service/node_modules/cluster-client/lib/leader.js:77:23)
    at listOnTimeout (internal/timers.js:549:17)
    at processTimers (internal/timers.js:492:7)
name: "ClusterClientNoResponseError"
pid: 75625
hostname: LEROLI-MB0

2020-11-29 00:09:21,556 ERROR 75625 nodejs.ClusterClientNoResponseError: client no response in 185363ms exceeding maxIdleTime 60000ms, maybe the connection is close on other side.
    at Timeout._onTimeout (/Users/lero/Documents/My-data/BLOG/blog_service/node_modules/cluster-client/lib/leader.js:77:23)
    at listOnTimeout (internal/timers.js:549:17)
    at processTimers (internal/timers.js:492:7)
name: "ClusterClientNoResponseError"
pid: 75625
hostname: LEROLI-MB0

2020-11-29 00:48:22,038 ERROR 75625 nodejs.ClusterClientNoResponseError: client no response in 2320471ms exceeding maxIdleTime 60000ms, maybe the connection is close on other side.
    at Timeout._onTimeout (/Users/lero/Documents/My-data/BLOG/blog_service/node_modules/cluster-client/lib/leader.js:77:23)
    at listOnTimeout (internal/timers.js:549:17)
    at processTimers (internal/timers.js:492:7)
name: "ClusterClientNoResponseError"
pid: 75625
hostname: LEROLI-MB0

2020-11-29 02:49:19,791 ERROR 75625 nodejs.ClusterClientNoResponseError: client no response in 7217755ms exceeding maxIdleTime 60000ms, maybe the connection is close on other side.
    at Timeout._onTimeout (/Users/lero/Documents/My-data/BLOG/blog_service/node_modules/cluster-client/lib/leader.js:77:23)
    at listOnTimeout (internal/timers.js:549:17)
    at processTimers (internal/timers.js:492:7)
name: "ClusterClientNoResponseError"
pid: 75625
hostname: LEROLI-MB0

2020-11-29 04:41:14,138 ERROR 75625 nodejs.ClusterClientNoResponseError: client no response in 6674411ms exceeding maxIdleTime 60000ms, maybe the connection is close on other side.
    at Timeout._onTimeout (/Users/lero/Documents/My-data/BLOG/blog_service/node_modules/cluster-client/lib/leader.js:77:23)
    at listOnTimeout (internal/timers.js:549:17)
    at processTimers (internal/timers.js:492:7)
name: "ClusterClientNoResponseError"
pid: 75625
hostname: LEROLI-MB0

2020-11-29 05:15:18,492 ERROR 75625 nodejs.ClusterClientNoResponseError: client no response in 2004424ms exceeding maxIdleTime 60000ms, maybe the connection is close on other side.
    at Timeout._onTimeout (/Users/lero/Documents/My-data/BLOG/blog_service/node_modules/cluster-client/lib/leader.js:77:23)
    at listOnTimeout (internal/timers.js:549:17)
    at processTimers (internal/timers.js:492:7)
name: "ClusterClientNoResponseError"
pid: 75625
hostname: LEROLI-MB0

2020-11-29 07:16:15,479 ERROR 75625 nodejs.ClusterClientNoResponseError: client no response in 7216996ms exceeding maxIdleTime 60000ms, maybe the connection is close on other side.
    at Timeout._onTimeout (/Users/lero/Documents/My-data/BLOG/blog_service/node_modules/cluster-client/lib/leader.js:77:23)
    at listOnTimeout (internal/timers.js:549:17)
    at processTimers (internal/timers.js:492:7)
name: "ClusterClientNoResponseError"
pid: 75625
hostname: LEROLI-MB0

2020-11-29 09:17:13,562 ERROR 75625 nodejs.ClusterClientNoResponseError: client no response in 7218061ms exceeding maxIdleTime 60000ms, maybe the connection is close on other side.
    at Timeout._onTimeout (/Users/lero/Documents/My-data/BLOG/blog_service/node_modules/cluster-client/lib/leader.js:77:23)
    at listOnTimeout (internal/timers.js:549:17)
    at processTimers (internal/timers.js:492:7)
name: "ClusterClientNoResponseError"
pid: 75625
hostname: LEROLI-MB0

2020-11-29 10:18:11,031 ERROR 75625 nodejs.ClusterClientNoResponseError: client no response in 3617518ms exceeding maxIdleTime 60000ms, maybe the connection is close on other side.
    at Timeout._onTimeout (/Users/lero/Documents/My-data/BLOG/blog_service/node_modules/cluster-client/lib/leader.js:77:23)
    at listOnTimeout (internal/timers.js:549:17)
    at processTimers (internal/timers.js:492:7)
name: "ClusterClientNoResponseError"
pid: 75625
hostname: LEROLI-MB0

2020-11-29 11:18:30,831 ERROR 75625 nodejs.ClusterClientNoResponseError: client no response in 3619798ms exceeding maxIdleTime 60000ms, maybe the connection is close on other side.
    at Timeout._onTimeout (/Users/lero/Documents/My-data/BLOG/blog_service/node_modules/cluster-client/lib/leader.js:77:23)
    at listOnTimeout (internal/timers.js:549:17)
    at processTimers (internal/timers.js:492:7)
name: "ClusterClientNoResponseError"
pid: 75625
hostname: LEROLI-MB0

2020-11-29 11:50:09,114 ERROR 75625 nodejs.ClusterClientNoResponseError: client no response in 1878268ms exceeding maxIdleTime 60000ms, maybe the connection is close on other side.
    at Timeout._onTimeout (/Users/lero/Documents/My-data/BLOG/blog_service/node_modules/cluster-client/lib/leader.js:77:23)
    at listOnTimeout (internal/timers.js:549:17)
    at processTimers (internal/timers.js:492:7)
name: "ClusterClientNoResponseError"
pid: 75625
hostname: LEROLI-MB0

2020-11-29 12:51:07,761 ERROR 75625 nodejs.ClusterClientNoResponseError: client no response in 3618667ms exceeding maxIdleTime 60000ms, maybe the connection is close on other side.
    at Timeout._onTimeout (/Users/lero/Documents/My-data/BLOG/blog_service/node_modules/cluster-client/lib/leader.js:77:23)
    at listOnTimeout (internal/timers.js:549:17)
    at processTimers (internal/timers.js:492:7)
name: "ClusterClientNoResponseError"
pid: 75625
hostname: LEROLI-MB0

2020-11-29 13:52:06,616 ERROR 75625 nodejs.ClusterClientNoResponseError: client no response in 3618839ms exceeding maxIdleTime 60000ms, maybe the connection is close on other side.
    at Timeout._onTimeout (/Users/lero/Documents/My-data/BLOG/blog_service/node_modules/cluster-client/lib/leader.js:77:23)
    at listOnTimeout (internal/timers.js:549:17)
    at processTimers (internal/timers.js:492:7)
name: "ClusterClientNoResponseError"
pid: 75625
hostname: LEROLI-MB0

2020-11-29 15:41:14,078 ERROR 75625 nodejs.ClusterClientNoResponseError: client no response in 6507449ms exceeding maxIdleTime 60000ms, maybe the connection is close on other side.
    at Timeout._onTimeout (/Users/lero/Documents/My-data/BLOG/blog_service/node_modules/cluster-client/lib/leader.js:77:23)
    at listOnTimeout (internal/timers.js:549:17)
    at processTimers (internal/timers.js:492:7)
name: "ClusterClientNoResponseError"
pid: 75625
hostname: LEROLI-MB0

2020-11-29 16:43:47,838 ERROR 75625 nodejs.ClusterClientNoResponseError: client no response in 3713740ms exceeding maxIdleTime 60000ms, maybe the connection is close on other side.
    at Timeout._onTimeout (/Users/lero/Documents/My-data/BLOG/blog_service/node_modules/cluster-client/lib/leader.js:77:23)
    at listOnTimeout (internal/timers.js:549:17)
    at processTimers (internal/timers.js:492:7)
name: "ClusterClientNoResponseError"
pid: 75625
hostname: LEROLI-MB0

2020-11-29 17:14:00,650 ERROR 75625 nodejs.ClusterClientNoResponseError: client no response in 1772800ms exceeding maxIdleTime 60000ms, maybe the connection is close on other side.
    at Timeout._onTimeout (/Users/lero/Documents/My-data/BLOG/blog_service/node_modules/cluster-client/lib/leader.js:77:23)
    at listOnTimeout (internal/timers.js:549:17)
    at processTimers (internal/timers.js:492:7)
name: "ClusterClientNoResponseError"
pid: 75625
hostname: LEROLI-MB0

2020-11-29 17:33:56,254 ERROR 75625 nodejs.ClusterClientNoResponseError: client no response in 1175605ms exceeding maxIdleTime 60000ms, maybe the connection is close on other side.
    at Timeout._onTimeout (/Users/lero/Documents/My-data/BLOG/blog_service/node_modules/cluster-client/lib/leader.js:77:23)
    at listOnTimeout (internal/timers.js:549:17)
    at processTimers (internal/timers.js:492:7)
name: "ClusterClientNoResponseError"
pid: 75625
hostname: LEROLI-MB0

2020-11-29 17:39:37,929 ERROR 75625 nodejs.ClusterClientNoResponseError: client no response in 301677ms exceeding maxIdleTime 60000ms, maybe the connection is close on other side.
    at Timeout._onTimeout (/Users/lero/Documents/My-data/BLOG/blog_service/node_modules/cluster-client/lib/leader.js:77:23)
    at listOnTimeout (internal/timers.js:549:17)
    at processTimers (internal/timers.js:492:7)
name: "ClusterClientNoResponseError"
pid: 75625
hostname: LEROLI-MB0

2020-11-29 17:45:50,505 ERROR 75625 nodejs.ClusterClientNoResponseError: client no response in 332570ms exceeding maxIdleTime 60000ms, maybe the connection is close on other side.
    at Timeout._onTimeout (/Users/lero/Documents/My-data/BLOG/blog_service/node_modules/cluster-client/lib/leader.js:77:23)
    at listOnTimeout (internal/timers.js:549:17)
    at processTimers (internal/timers.js:492:7)
name: "ClusterClientNoResponseError"
pid: 75625
hostname: LEROLI-MB0

2020-11-29 17:53:28,747 ERROR 75625 nodejs.ClusterClientNoResponseError: client no response in 418225ms exceeding maxIdleTime 60000ms, maybe the connection is close on other side.
    at Timeout._onTimeout (/Users/lero/Documents/My-data/BLOG/blog_service/node_modules/cluster-client/lib/leader.js:77:23)
    at listOnTimeout (internal/timers.js:549:17)
    at processTimers (internal/timers.js:492:7)
name: "ClusterClientNoResponseError"
pid: 75625
hostname: LEROLI-MB0

2020-11-29 17:55:05,145 ERROR 75625 nodejs.ClusterClientNoResponseError: client no response in 76385ms exceeding maxIdleTime 60000ms, maybe the connection is close on other side.
    at Timeout._onTimeout (/Users/lero/Documents/My-data/BLOG/blog_service/node_modules/cluster-client/lib/leader.js:77:23)
    at listOnTimeout (internal/timers.js:549:17)
    at processTimers (internal/timers.js:492:7)
name: "ClusterClientNoResponseError"
pid: 75625
hostname: LEROLI-MB0

2020-11-29 18:03:00,811 ERROR 75625 nodejs.ClusterClientNoResponseError: client no response in 435655ms exceeding maxIdleTime 60000ms, maybe the connection is close on other side.
    at Timeout._onTimeout (/Users/lero/Documents/My-data/BLOG/blog_service/node_modules/cluster-client/lib/leader.js:77:23)
    at listOnTimeout (internal/timers.js:549:17)
    at processTimers (internal/timers.js:492:7)
name: "ClusterClientNoResponseError"
pid: 75625
hostname: LEROLI-MB0

2020-11-29 18:08:42,532 ERROR 75625 nodejs.ClusterClientNoResponseError: client no response in 301713ms exceeding maxIdleTime 60000ms, maybe the connection is close on other side.
    at Timeout._onTimeout (/Users/lero/Documents/My-data/BLOG/blog_service/node_modules/cluster-client/lib/leader.js:77:23)
    at listOnTimeout (internal/timers.js:549:17)
    at processTimers (internal/timers.js:492:7)
name: "ClusterClientNoResponseError"
pid: 75625
hostname: LEROLI-MB0

2020-11-29 18:14:24,224 ERROR 75625 nodejs.ClusterClientNoResponseError: client no response in 301674ms exceeding maxIdleTime 60000ms, maybe the connection is close on other side.
    at Timeout._onTimeout (/Users/lero/Documents/My-data/BLOG/blog_service/node_modules/cluster-client/lib/leader.js:77:23)
    at listOnTimeout (internal/timers.js:549:17)
    at processTimers (internal/timers.js:492:7)
name: "ClusterClientNoResponseError"
pid: 75625
hostname: LEROLI-MB0

2020-11-29 18:19:45,943 ERROR 75625 nodejs.ClusterClientNoResponseError: client no response in 301706ms exceeding maxIdleTime 60000ms, maybe the connection is close on other side.
    at Timeout._onTimeout (/Users/lero/Documents/My-data/BLOG/blog_service/node_modules/cluster-client/lib/leader.js:77:23)
    at listOnTimeout (internal/timers.js:549:17)
    at processTimers (internal/timers.js:492:7)
name: "ClusterClientNoResponseError"
pid: 75625
hostname: LEROLI-MB0

2020-11-29 18:25:27,679 ERROR 75625 nodejs.ClusterClientNoResponseError: client no response in 301721ms exceeding maxIdleTime 60000ms, maybe the connection is close on other side.
    at Timeout._onTimeout (/Users/lero/Documents/My-data/BLOG/blog_service/node_modules/cluster-client/lib/leader.js:77:23)
    at listOnTimeout (internal/timers.js:549:17)
    at processTimers (internal/timers.js:492:7)
name: "ClusterClientNoResponseError"
pid: 75625
hostname: LEROLI-MB0

2020-11-29 19:01:38,520 ERROR 75625 nodejs.ClusterClientNoResponseError: client no response in 2130825ms exceeding maxIdleTime 60000ms, maybe the connection is close on other side.
    at Timeout._onTimeout (/Users/lero/Documents/My-data/BLOG/blog_service/node_modules/cluster-client/lib/leader.js:77:23)
    at listOnTimeout (internal/timers.js:549:17)
    at processTimers (internal/timers.js:492:7)
name: "ClusterClientNoResponseError"
pid: 75625
hostname: LEROLI-MB0

2020-11-29 19:07:20,212 ERROR 75625 nodejs.ClusterClientNoResponseError: client no response in 301700ms exceeding maxIdleTime 60000ms, maybe the connection is close on other side.
    at Timeout._onTimeout (/Users/lero/Documents/My-data/BLOG/blog_service/node_modules/cluster-client/lib/leader.js:77:23)
    at listOnTimeout (internal/timers.js:549:17)
    at processTimers (internal/timers.js:492:7)
name: "ClusterClientNoResponseError"
pid: 75625
hostname: LEROLI-MB0

2020-11-29 19:12:41,939 ERROR 75625 nodejs.ClusterClientNoResponseError: client no response in 301721ms exceeding maxIdleTime 60000ms, maybe the connection is close on other side.
    at Timeout._onTimeout (/Users/lero/Documents/My-data/BLOG/blog_service/node_modules/cluster-client/lib/leader.js:77:23)
    at listOnTimeout (internal/timers.js:549:17)
    at processTimers (internal/timers.js:492:7)
name: "ClusterClientNoResponseError"
pid: 75625
hostname: LEROLI-MB0

2020-11-29 19:24:10,299 ERROR 75625 nodejs.ClusterClientNoResponseError: client no response in 306690ms exceeding maxIdleTime 60000ms, maybe the connection is close on other side.
    at Timeout._onTimeout (/Users/lero/Documents/My-data/BLOG/blog_service/node_modules/cluster-client/lib/leader.js:77:23)
    at listOnTimeout (internal/timers.js:549:17)
    at processTimers (internal/timers.js:492:7)
name: "ClusterClientNoResponseError"
pid: 75625
hostname: LEROLI-MB0

2020-11-29 19:30:55,679 ERROR 75625 nodejs.ClusterClientNoResponseError: client no response in 301697ms exceeding maxIdleTime 60000ms, maybe the connection is close on other side.
    at Timeout._onTimeout (/Users/lero/Documents/My-data/BLOG/blog_service/node_modules/cluster-client/lib/leader.js:77:23)
    at listOnTimeout (internal/timers.js:549:17)
    at processTimers (internal/timers.js:492:7)
name: "ClusterClientNoResponseError"
pid: 75625
hostname: LEROLI-MB0

2020-11-29 19:47:30,722 ERROR 75625 nodejs.ClusterClientNoResponseError: client no response in 935019ms exceeding maxIdleTime 60000ms, maybe the connection is close on other side.
    at Timeout._onTimeout (/Users/lero/Documents/My-data/BLOG/blog_service/node_modules/cluster-client/lib/leader.js:77:23)
    at listOnTimeout (internal/timers.js:549:17)
    at processTimers (internal/timers.js:492:7)
name: "ClusterClientNoResponseError"
pid: 75625
hostname: LEROLI-MB0

2020-11-29 20:50:34,266 ERROR 75625 nodejs.ClusterClientNoResponseError: client no response in 3617336ms exceeding maxIdleTime 60000ms, maybe the connection is close on other side.
    at Timeout._onTimeout (/Users/lero/Documents/My-data/BLOG/blog_service/node_modules/cluster-client/lib/leader.js:77:23)
    at listOnTimeout (internal/timers.js:549:17)
    at processTimers (internal/timers.js:492:7)
name: "ClusterClientNoResponseError"
pid: 75625
hostname: LEROLI-MB0

2020-11-29 21:06:57,990 ERROR 75625 nodejs.ClusterClientNoResponseError: client no response in 943698ms exceeding maxIdleTime 60000ms, maybe the connection is close on other side.
    at Timeout._onTimeout (/Users/lero/Documents/My-data/BLOG/blog_service/node_modules/cluster-client/lib/leader.js:77:23)
    at listOnTimeout (internal/timers.js:549:17)
    at processTimers (internal/timers.js:492:7)
name: "ClusterClientNoResponseError"
pid: 75625
hostname: LEROLI-MB0

2020-11-29 21:17:56,435 ERROR 75625 nodejs.ClusterClientNoResponseError: client no response in 638435ms exceeding maxIdleTime 60000ms, maybe the connection is close on other side.
    at Timeout._onTimeout (/Users/lero/Documents/My-data/BLOG/blog_service/node_modules/cluster-client/lib/leader.js:77:23)
    at listOnTimeout (internal/timers.js:549:17)
    at processTimers (internal/timers.js:492:7)
name: "ClusterClientNoResponseError"
pid: 75625
hostname: LEROLI-MB0

2020-11-29 21:25:52,087 ERROR 75625 nodejs.ClusterClientNoResponseError: client no response in 435647ms exceeding maxIdleTime 60000ms, maybe the connection is close on other side.
    at Timeout._onTimeout (/Users/lero/Documents/My-data/BLOG/blog_service/node_modules/cluster-client/lib/leader.js:77:23)
    at listOnTimeout (internal/timers.js:549:17)
    at processTimers (internal/timers.js:492:7)
name: "ClusterClientNoResponseError"
pid: 75625
hostname: LEROLI-MB0

2020-11-29 21:30:12,001 ERROR 75625 nodejs.ClusterClientNoResponseError: client no response in 219899ms exceeding maxIdleTime 60000ms, maybe the connection is close on other side.
    at Timeout._onTimeout (/Users/lero/Documents/My-data/BLOG/blog_service/node_modules/cluster-client/lib/leader.js:77:23)
    at listOnTimeout (internal/timers.js:549:17)
    at processTimers (internal/timers.js:492:7)
name: "ClusterClientNoResponseError"
pid: 75625
hostname: LEROLI-MB0

2020-11-29 22:34:54,884 ERROR 75625 nodejs.ClusterClientNoResponseError: client no response in 301749ms exceeding maxIdleTime 60000ms, maybe the connection is close on other side.
    at Timeout._onTimeout (/Users/lero/Documents/My-data/BLOG/blog_service/node_modules/cluster-client/lib/leader.js:77:23)
    at listOnTimeout (internal/timers.js:549:17)
    at processTimers (internal/timers.js:492:7)
name: "ClusterClientNoResponseError"
pid: 75625
hostname: LEROLI-MB0

2020-11-29 22:40:36,591 ERROR 75625 nodejs.ClusterClientNoResponseError: client no response in 301683ms exceeding maxIdleTime 60000ms, maybe the connection is close on other side.
    at Timeout._onTimeout (/Users/lero/Documents/My-data/BLOG/blog_service/node_modules/cluster-client/lib/leader.js:77:23)
    at listOnTimeout (internal/timers.js:549:17)
    at processTimers (internal/timers.js:492:7)
name: "ClusterClientNoResponseError"
pid: 75625
hostname: LEROLI-MB0

2020-11-29 22:43:31,738 ERROR 75625 nodejs.ClusterClientNoResponseError: client no response in 135138ms exceeding maxIdleTime 60000ms, maybe the connection is close on other side.
    at Timeout._onTimeout (/Users/lero/Documents/My-data/BLOG/blog_service/node_modules/cluster-client/lib/leader.js:77:23)
    at listOnTimeout (internal/timers.js:549:17)
    at processTimers (internal/timers.js:492:7)
name: "ClusterClientNoResponseError"
pid: 75625
hostname: LEROLI-MB0

2020-11-29 22:48:55,192 ERROR 75625 nodejs.ClusterClientNoResponseError: client no response in 303440ms exceeding maxIdleTime 60000ms, maybe the connection is close on other side.
    at Timeout._onTimeout (/Users/lero/Documents/My-data/BLOG/blog_service/node_modules/cluster-client/lib/leader.js:77:23)
    at listOnTimeout (internal/timers.js:549:17)
    at processTimers (internal/timers.js:492:7)
name: "ClusterClientNoResponseError"
pid: 75625
hostname: LEROLI-MB0

2020-11-29 22:53:37,101 ERROR 75625 nodejs.ClusterClientNoResponseError: client no response in 207806ms exceeding maxIdleTime 60000ms, maybe the connection is close on other side.
    at Timeout._onTimeout (/Users/lero/Documents/My-data/BLOG/blog_service/node_modules/cluster-client/lib/leader.js:77:23)
    at listOnTimeout (internal/timers.js:549:17)
    at processTimers (internal/timers.js:492:7)
name: "ClusterClientNoResponseError"
pid: 75625
hostname: LEROLI-MB0

2020-11-29 22:58:45,896 ERROR 75625 nodejs.ClusterClientNoResponseError: client no response in 308716ms exceeding maxIdleTime 60000ms, maybe the connection is close on other side.
    at Timeout._onTimeout (/Users/lero/Documents/My-data/BLOG/blog_service/node_modules/cluster-client/lib/leader.js:77:23)
    at listOnTimeout (internal/timers.js:549:17)
    at processTimers (internal/timers.js:492:7)
name: "ClusterClientNoResponseError"
pid: 75625
hostname: LEROLI-MB0

2020-11-30 08:45:10,838 ERROR 75625 nodejs.ClusterClientNoResponseError: client no response in 35164903ms exceeding maxIdleTime 60000ms, maybe the connection is close on other side.
    at Timeout._onTimeout (/Users/lero/Documents/My-data/BLOG/blog_service/node_modules/cluster-client/lib/leader.js:77:23)
    at listOnTimeout (internal/timers.js:549:17)
    at processTimers (internal/timers.js:492:7)
name: "ClusterClientNoResponseError"
pid: 75625
hostname: LEROLI-MB0

2020-11-30 09:35:37,982 ERROR 75625 nodejs.ClusterClientNoResponseError: client no response in 3027131ms exceeding maxIdleTime 60000ms, maybe the connection is close on other side.
    at Timeout._onTimeout (/Users/lero/Documents/My-data/BLOG/blog_service/node_modules/cluster-client/lib/leader.js:77:23)
    at listOnTimeout (internal/timers.js:549:17)
    at processTimers (internal/timers.js:492:7)
name: "ClusterClientNoResponseError"
pid: 75625
hostname: LEROLI-MB0

2020-11-30 09:53:33,959 ERROR 75625 nodejs.ClusterClientNoResponseError: client no response in 1055960ms exceeding maxIdleTime 60000ms, maybe the connection is close on other side.
    at Timeout._onTimeout (/Users/lero/Documents/My-data/BLOG/blog_service/node_modules/cluster-client/lib/leader.js:77:23)
    at listOnTimeout (internal/timers.js:549:17)
    at processTimers (internal/timers.js:492:7)
name: "ClusterClientNoResponseError"
pid: 75625
hostname: LEROLI-MB0

2020-11-30 09:54:37,624 ERROR 75625 nodejs.ClusterClientNoResponseError: client no response in 63652ms exceeding maxIdleTime 60000ms, maybe the connection is close on other side.
    at Timeout._onTimeout (/Users/lero/Documents/My-data/BLOG/blog_service/node_modules/cluster-client/lib/leader.js:77:23)
    at listOnTimeout (internal/timers.js:549:17)
    at processTimers (internal/timers.js:492:7)
name: "ClusterClientNoResponseError"
pid: 75625
hostname: LEROLI-MB0

2020-12-15 18:45:06,467 ERROR 64750 [-/127.0.0.1/-/1ms GET /] nodejs.ER_NOT_SUPPORTED_AUTH_MODEError: ER_NOT_SUPPORTED_AUTH_MODE: Client does not support authentication protocol requested by server; consider upgrading MySQL client
    at Handshake.Sequence._packetToError (/Users/lero/Documents/My-data/BLOG/blog_service/node_modules/mysql/lib/protocol/sequences/Sequence.js:47:14)
    at Handshake.ErrorPacket (/Users/lero/Documents/My-data/BLOG/blog_service/node_modules/mysql/lib/protocol/sequences/Handshake.js:123:18)
    at Protocol._parsePacket (/Users/lero/Documents/My-data/BLOG/blog_service/node_modules/mysql/lib/protocol/Protocol.js:291:23)
    at Parser._parsePacket (/Users/lero/Documents/My-data/BLOG/blog_service/node_modules/mysql/lib/protocol/Parser.js:433:10)
    at Parser.write (/Users/lero/Documents/My-data/BLOG/blog_service/node_modules/mysql/lib/protocol/Parser.js:43:10)
    at Protocol.write (/Users/lero/Documents/My-data/BLOG/blog_service/node_modules/mysql/lib/protocol/Protocol.js:38:16)
    at Socket.<anonymous> (/Users/lero/Documents/My-data/BLOG/blog_service/node_modules/mysql/lib/Connection.js:88:28)
    at Socket.<anonymous> (/Users/lero/Documents/My-data/BLOG/blog_service/node_modules/mysql/lib/Connection.js:526:10)
    at Socket.emit (events.js:315:20)
    at addChunk (_stream_readable.js:297:12)
    --------------------
    at Protocol._enqueue (/Users/lero/Documents/My-data/BLOG/blog_service/node_modules/mysql/lib/protocol/Protocol.js:144:48)
    at Protocol.handshake (/Users/lero/Documents/My-data/BLOG/blog_service/node_modules/mysql/lib/protocol/Protocol.js:51:23)
    at PoolConnection.connect (/Users/lero/Documents/My-data/BLOG/blog_service/node_modules/mysql/lib/Connection.js:116:18)
    at Pool.getConnection (/Users/lero/Documents/My-data/BLOG/blog_service/node_modules/mysql/lib/Pool.js:48:16)
    at /Users/lero/Documents/My-data/BLOG/blog_service/node_modules/ali-rds/node_modules/pify/index.js:29:7
    at new Promise (<anonymous>)
    at Pool.<anonymous> (/Users/lero/Documents/My-data/BLOG/blog_service/node_modules/ali-rds/node_modules/pify/index.js:12:10)
    at Pool.ret [as getConnection] (/Users/lero/Documents/My-data/BLOG/blog_service/node_modules/ali-rds/node_modules/pify/index.js:56:34)
    at Pool.query (/Users/lero/Documents/My-data/BLOG/blog_service/node_modules/mysql/lib/Pool.js:202:8)
    at /Users/lero/Documents/My-data/BLOG/blog_service/node_modules/ali-rds/node_modules/pify/index.js:29:7
    sql: select now() as currentTime;
code: "ER_NOT_SUPPORTED_AUTH_MODE"
errno: 1251
sqlMessage: "Client does not support authentication protocol requested by server; consider upgrading MySQL client"
sqlState: "08004"
fatal: true
name: "ER_NOT_SUPPORTED_AUTH_MODEError"
pid: 64750
hostname: LEROLI-MB0

2020-12-15 18:46:24,928 ERROR 64927 [-/127.0.0.1/-/0ms GET /] nodejs.ER_NOT_SUPPORTED_AUTH_MODEError: ER_NOT_SUPPORTED_AUTH_MODE: Client does not support authentication protocol requested by server; consider upgrading MySQL client
    at Handshake.Sequence._packetToError (/Users/lero/Documents/My-data/BLOG/blog_service/node_modules/mysql/lib/protocol/sequences/Sequence.js:47:14)
    at Handshake.ErrorPacket (/Users/lero/Documents/My-data/BLOG/blog_service/node_modules/mysql/lib/protocol/sequences/Handshake.js:123:18)
    at Protocol._parsePacket (/Users/lero/Documents/My-data/BLOG/blog_service/node_modules/mysql/lib/protocol/Protocol.js:291:23)
    at Parser._parsePacket (/Users/lero/Documents/My-data/BLOG/blog_service/node_modules/mysql/lib/protocol/Parser.js:433:10)
    at Parser.write (/Users/lero/Documents/My-data/BLOG/blog_service/node_modules/mysql/lib/protocol/Parser.js:43:10)
    at Protocol.write (/Users/lero/Documents/My-data/BLOG/blog_service/node_modules/mysql/lib/protocol/Protocol.js:38:16)
    at Socket.<anonymous> (/Users/lero/Documents/My-data/BLOG/blog_service/node_modules/mysql/lib/Connection.js:88:28)
    at Socket.<anonymous> (/Users/lero/Documents/My-data/BLOG/blog_service/node_modules/mysql/lib/Connection.js:526:10)
    at Socket.emit (events.js:315:20)
    at addChunk (_stream_readable.js:297:12)
    --------------------
    at Protocol._enqueue (/Users/lero/Documents/My-data/BLOG/blog_service/node_modules/mysql/lib/protocol/Protocol.js:144:48)
    at Protocol.handshake (/Users/lero/Documents/My-data/BLOG/blog_service/node_modules/mysql/lib/protocol/Protocol.js:51:23)
    at PoolConnection.connect (/Users/lero/Documents/My-data/BLOG/blog_service/node_modules/mysql/lib/Connection.js:116:18)
    at Pool.getConnection (/Users/lero/Documents/My-data/BLOG/blog_service/node_modules/mysql/lib/Pool.js:48:16)
    at /Users/lero/Documents/My-data/BLOG/blog_service/node_modules/ali-rds/node_modules/pify/index.js:29:7
    at new Promise (<anonymous>)
    at Pool.<anonymous> (/Users/lero/Documents/My-data/BLOG/blog_service/node_modules/ali-rds/node_modules/pify/index.js:12:10)
    at Pool.ret [as getConnection] (/Users/lero/Documents/My-data/BLOG/blog_service/node_modules/ali-rds/node_modules/pify/index.js:56:34)
    at Pool.query (/Users/lero/Documents/My-data/BLOG/blog_service/node_modules/mysql/lib/Pool.js:202:8)
    at /Users/lero/Documents/My-data/BLOG/blog_service/node_modules/ali-rds/node_modules/pify/index.js:29:7
    sql: select now() as currentTime;
code: "ER_NOT_SUPPORTED_AUTH_MODE"
errno: 1251
sqlMessage: "Client does not support authentication protocol requested by server; consider upgrading MySQL client"
sqlState: "08004"
fatal: true
name: "ER_NOT_SUPPORTED_AUTH_MODEError"
pid: 64927
hostname: LEROLI-MB0

2020-12-15 19:07:11,173 ERROR 67661 [-/127.0.0.1/-/0ms GET /] nodejs.PROTOCOL_SEQUENCE_TIMEOUTError: Handshake inactivity timeout
    at Handshake.<anonymous> (/Users/lero/Documents/My-data/BLOG/blog_service/node_modules/mysql/lib/protocol/Protocol.js:160:17)
    at Handshake.emit (events.js:315:20)
    at Handshake._onTimeout (/Users/lero/Documents/My-data/BLOG/blog_service/node_modules/mysql/lib/protocol/sequences/Sequence.js:124:8)
    at Timer._onTimeout (/Users/lero/Documents/My-data/BLOG/blog_service/node_modules/mysql/lib/protocol/Timer.js:32:23)
    at listOnTimeout (internal/timers.js:549:17)
    at processTimers (internal/timers.js:492:7)
    --------------------
    at Protocol._enqueue (/Users/lero/Documents/My-data/BLOG/blog_service/node_modules/mysql/lib/protocol/Protocol.js:144:48)
    at Protocol.handshake (/Users/lero/Documents/My-data/BLOG/blog_service/node_modules/mysql/lib/protocol/Protocol.js:51:23)
    at PoolConnection.connect (/Users/lero/Documents/My-data/BLOG/blog_service/node_modules/mysql/lib/Connection.js:116:18)
    at Pool.getConnection (/Users/lero/Documents/My-data/BLOG/blog_service/node_modules/mysql/lib/Pool.js:48:16)
    at /Users/lero/Documents/My-data/BLOG/blog_service/node_modules/ali-rds/node_modules/pify/index.js:29:7
    at new Promise (<anonymous>)
    at Pool.<anonymous> (/Users/lero/Documents/My-data/BLOG/blog_service/node_modules/ali-rds/node_modules/pify/index.js:12:10)
    at Pool.ret [as getConnection] (/Users/lero/Documents/My-data/BLOG/blog_service/node_modules/ali-rds/node_modules/pify/index.js:56:34)
    at Pool.query (/Users/lero/Documents/My-data/BLOG/blog_service/node_modules/mysql/lib/Pool.js:202:8)
    at /Users/lero/Documents/My-data/BLOG/blog_service/node_modules/ali-rds/node_modules/pify/index.js:29:7
    sql: select now() as currentTime;
code: "PROTOCOL_SEQUENCE_TIMEOUT"
fatal: true
timeout: 10000
name: "PROTOCOL_SEQUENCE_TIMEOUTError"
pid: 67661
hostname: LEROLI-MB0

2020-12-15 19:13:54,148 ERROR 68637 [-/127.0.0.1/-/0ms GET /] nodejs.ER_NOT_SUPPORTED_AUTH_MODEError: ER_NOT_SUPPORTED_AUTH_MODE: Client does not support authentication protocol requested by server; consider upgrading MySQL client
    at Handshake.Sequence._packetToError (/Users/lero/Documents/My-data/BLOG/blog_service/node_modules/mysql/lib/protocol/sequences/Sequence.js:47:14)
    at Handshake.ErrorPacket (/Users/lero/Documents/My-data/BLOG/blog_service/node_modules/mysql/lib/protocol/sequences/Handshake.js:123:18)
    at Protocol._parsePacket (/Users/lero/Documents/My-data/BLOG/blog_service/node_modules/mysql/lib/protocol/Protocol.js:291:23)
    at Parser._parsePacket (/Users/lero/Documents/My-data/BLOG/blog_service/node_modules/mysql/lib/protocol/Parser.js:433:10)
    at Parser.write (/Users/lero/Documents/My-data/BLOG/blog_service/node_modules/mysql/lib/protocol/Parser.js:43:10)
    at Protocol.write (/Users/lero/Documents/My-data/BLOG/blog_service/node_modules/mysql/lib/protocol/Protocol.js:38:16)
    at Socket.<anonymous> (/Users/lero/Documents/My-data/BLOG/blog_service/node_modules/mysql/lib/Connection.js:88:28)
    at Socket.<anonymous> (/Users/lero/Documents/My-data/BLOG/blog_service/node_modules/mysql/lib/Connection.js:526:10)
    at Socket.emit (events.js:315:20)
    at addChunk (_stream_readable.js:297:12)
    --------------------
    at Protocol._enqueue (/Users/lero/Documents/My-data/BLOG/blog_service/node_modules/mysql/lib/protocol/Protocol.js:144:48)
    at Protocol.handshake (/Users/lero/Documents/My-data/BLOG/blog_service/node_modules/mysql/lib/protocol/Protocol.js:51:23)
    at PoolConnection.connect (/Users/lero/Documents/My-data/BLOG/blog_service/node_modules/mysql/lib/Connection.js:116:18)
    at Pool.getConnection (/Users/lero/Documents/My-data/BLOG/blog_service/node_modules/mysql/lib/Pool.js:48:16)
    at /Users/lero/Documents/My-data/BLOG/blog_service/node_modules/ali-rds/node_modules/pify/index.js:29:7
    at new Promise (<anonymous>)
    at Pool.<anonymous> (/Users/lero/Documents/My-data/BLOG/blog_service/node_modules/ali-rds/node_modules/pify/index.js:12:10)
    at Pool.ret [as getConnection] (/Users/lero/Documents/My-data/BLOG/blog_service/node_modules/ali-rds/node_modules/pify/index.js:56:34)
    at Pool.query (/Users/lero/Documents/My-data/BLOG/blog_service/node_modules/mysql/lib/Pool.js:202:8)
    at /Users/lero/Documents/My-data/BLOG/blog_service/node_modules/ali-rds/node_modules/pify/index.js:29:7
    sql: select now() as currentTime;
code: "ER_NOT_SUPPORTED_AUTH_MODE"
errno: 1251
sqlMessage: "Client does not support authentication protocol requested by server; consider upgrading MySQL client"
sqlState: "08004"
fatal: true
name: "ER_NOT_SUPPORTED_AUTH_MODEError"
pid: 68637
hostname: LEROLI-MB0

2020-12-15 19:23:12,260 ERROR 70224 [-/127.0.0.1/-/0ms GET /] nodejs.ER_BAD_DB_ERRORError: ER_BAD_DB_ERROR: Unknown database 'blog'
    at Handshake.Sequence._packetToError (/Users/lero/Documents/My-data/BLOG/blog_service/node_modules/mysql/lib/protocol/sequences/Sequence.js:47:14)
    at Handshake.ErrorPacket (/Users/lero/Documents/My-data/BLOG/blog_service/node_modules/mysql/lib/protocol/sequences/Handshake.js:123:18)
    at Protocol._parsePacket (/Users/lero/Documents/My-data/BLOG/blog_service/node_modules/mysql/lib/protocol/Protocol.js:291:23)
    at Parser._parsePacket (/Users/lero/Documents/My-data/BLOG/blog_service/node_modules/mysql/lib/protocol/Parser.js:433:10)
    at Parser.write (/Users/lero/Documents/My-data/BLOG/blog_service/node_modules/mysql/lib/protocol/Parser.js:43:10)
    at Protocol.write (/Users/lero/Documents/My-data/BLOG/blog_service/node_modules/mysql/lib/protocol/Protocol.js:38:16)
    at Socket.<anonymous> (/Users/lero/Documents/My-data/BLOG/blog_service/node_modules/mysql/lib/Connection.js:88:28)
    at Socket.<anonymous> (/Users/lero/Documents/My-data/BLOG/blog_service/node_modules/mysql/lib/Connection.js:526:10)
    at Socket.emit (events.js:315:20)
    at addChunk (_stream_readable.js:297:12)
    --------------------
    at Protocol._enqueue (/Users/lero/Documents/My-data/BLOG/blog_service/node_modules/mysql/lib/protocol/Protocol.js:144:48)
    at Protocol.handshake (/Users/lero/Documents/My-data/BLOG/blog_service/node_modules/mysql/lib/protocol/Protocol.js:51:23)
    at PoolConnection.connect (/Users/lero/Documents/My-data/BLOG/blog_service/node_modules/mysql/lib/Connection.js:116:18)
    at Pool.getConnection (/Users/lero/Documents/My-data/BLOG/blog_service/node_modules/mysql/lib/Pool.js:48:16)
    at /Users/lero/Documents/My-data/BLOG/blog_service/node_modules/ali-rds/node_modules/pify/index.js:29:7
    at new Promise (<anonymous>)
    at Pool.<anonymous> (/Users/lero/Documents/My-data/BLOG/blog_service/node_modules/ali-rds/node_modules/pify/index.js:12:10)
    at Pool.ret [as getConnection] (/Users/lero/Documents/My-data/BLOG/blog_service/node_modules/ali-rds/node_modules/pify/index.js:56:34)
    at Pool.query (/Users/lero/Documents/My-data/BLOG/blog_service/node_modules/mysql/lib/Pool.js:202:8)
    at /Users/lero/Documents/My-data/BLOG/blog_service/node_modules/ali-rds/node_modules/pify/index.js:29:7
    sql: select now() as currentTime;
code: "ER_BAD_DB_ERROR"
errno: 1049
sqlMessage: "Unknown database 'blog'"
sqlState: "42000"
fatal: true
name: "ER_BAD_DB_ERRORError"
pid: 70224
hostname: LEROLI-MB0

2020-12-15 19:35:30,937 ERROR 71909 [-/127.0.0.1/-/0ms GET /] nodejs.ER_BAD_DB_ERRORError: ER_BAD_DB_ERROR: Unknown database 'blog_content'
    at Handshake.Sequence._packetToError (/Users/lero/Documents/My-data/BLOG/blog_service/node_modules/mysql/lib/protocol/sequences/Sequence.js:47:14)
    at Handshake.ErrorPacket (/Users/lero/Documents/My-data/BLOG/blog_service/node_modules/mysql/lib/protocol/sequences/Handshake.js:123:18)
    at Protocol._parsePacket (/Users/lero/Documents/My-data/BLOG/blog_service/node_modules/mysql/lib/protocol/Protocol.js:291:23)
    at Parser._parsePacket (/Users/lero/Documents/My-data/BLOG/blog_service/node_modules/mysql/lib/protocol/Parser.js:433:10)
    at Parser.write (/Users/lero/Documents/My-data/BLOG/blog_service/node_modules/mysql/lib/protocol/Parser.js:43:10)
    at Protocol.write (/Users/lero/Documents/My-data/BLOG/blog_service/node_modules/mysql/lib/protocol/Protocol.js:38:16)
    at Socket.<anonymous> (/Users/lero/Documents/My-data/BLOG/blog_service/node_modules/mysql/lib/Connection.js:88:28)
    at Socket.<anonymous> (/Users/lero/Documents/My-data/BLOG/blog_service/node_modules/mysql/lib/Connection.js:526:10)
    at Socket.emit (events.js:315:20)
    at addChunk (_stream_readable.js:297:12)
    --------------------
    at Protocol._enqueue (/Users/lero/Documents/My-data/BLOG/blog_service/node_modules/mysql/lib/protocol/Protocol.js:144:48)
    at Protocol.handshake (/Users/lero/Documents/My-data/BLOG/blog_service/node_modules/mysql/lib/protocol/Protocol.js:51:23)
    at PoolConnection.connect (/Users/lero/Documents/My-data/BLOG/blog_service/node_modules/mysql/lib/Connection.js:116:18)
    at Pool.getConnection (/Users/lero/Documents/My-data/BLOG/blog_service/node_modules/mysql/lib/Pool.js:48:16)
    at /Users/lero/Documents/My-data/BLOG/blog_service/node_modules/ali-rds/node_modules/pify/index.js:29:7
    at new Promise (<anonymous>)
    at Pool.<anonymous> (/Users/lero/Documents/My-data/BLOG/blog_service/node_modules/ali-rds/node_modules/pify/index.js:12:10)
    at Pool.ret [as getConnection] (/Users/lero/Documents/My-data/BLOG/blog_service/node_modules/ali-rds/node_modules/pify/index.js:56:34)
    at Pool.query (/Users/lero/Documents/My-data/BLOG/blog_service/node_modules/mysql/lib/Pool.js:202:8)
    at /Users/lero/Documents/My-data/BLOG/blog_service/node_modules/ali-rds/node_modules/pify/index.js:29:7
    sql: select now() as currentTime;
code: "ER_BAD_DB_ERROR"
errno: 1049
sqlMessage: "Unknown database 'blog_content'"
sqlState: "42000"
fatal: true
name: "ER_BAD_DB_ERRORError"
pid: 71909
hostname: LEROLI-MB0

2020-12-15 19:46:00,096 ERROR 73206 [-/127.0.0.1/-/0ms GET /] nodejs.PROTOCOL_SEQUENCE_TIMEOUTError: Handshake inactivity timeout
    at Handshake.<anonymous> (/Users/lero/Documents/My-data/BLOG/blog_service/node_modules/mysql/lib/protocol/Protocol.js:160:17)
    at Handshake.emit (events.js:315:20)
    at Handshake._onTimeout (/Users/lero/Documents/My-data/BLOG/blog_service/node_modules/mysql/lib/protocol/sequences/Sequence.js:124:8)
    at Timer._onTimeout (/Users/lero/Documents/My-data/BLOG/blog_service/node_modules/mysql/lib/protocol/Timer.js:32:23)
    at listOnTimeout (internal/timers.js:549:17)
    at processTimers (internal/timers.js:492:7)
    --------------------
    at Protocol._enqueue (/Users/lero/Documents/My-data/BLOG/blog_service/node_modules/mysql/lib/protocol/Protocol.js:144:48)
    at Protocol.handshake (/Users/lero/Documents/My-data/BLOG/blog_service/node_modules/mysql/lib/protocol/Protocol.js:51:23)
    at PoolConnection.connect (/Users/lero/Documents/My-data/BLOG/blog_service/node_modules/mysql/lib/Connection.js:116:18)
    at Pool.getConnection (/Users/lero/Documents/My-data/BLOG/blog_service/node_modules/mysql/lib/Pool.js:48:16)
    at /Users/lero/Documents/My-data/BLOG/blog_service/node_modules/ali-rds/node_modules/pify/index.js:29:7
    at new Promise (<anonymous>)
    at Pool.<anonymous> (/Users/lero/Documents/My-data/BLOG/blog_service/node_modules/ali-rds/node_modules/pify/index.js:12:10)
    at Pool.ret [as getConnection] (/Users/lero/Documents/My-data/BLOG/blog_service/node_modules/ali-rds/node_modules/pify/index.js:56:34)
    at Pool.query (/Users/lero/Documents/My-data/BLOG/blog_service/node_modules/mysql/lib/Pool.js:202:8)
    at /Users/lero/Documents/My-data/BLOG/blog_service/node_modules/ali-rds/node_modules/pify/index.js:29:7
    sql: select now() as currentTime;
code: "PROTOCOL_SEQUENCE_TIMEOUT"
fatal: true
timeout: 10000
name: "PROTOCOL_SEQUENCE_TIMEOUTError"
pid: 73206
hostname: LEROLI-MB0

2020-12-15 21:27:48,612 ERROR 85488 [-/127.0.0.1/-/149ms GET /api/v1/blog/list] nodejs.TypeError: result is not iterable
    at HomeController.index (/Users/lero/Documents/My-data/BLOG/blog_service/app/controller/default/home.js:13:17)
    at processTicksAndRejections (internal/process/task_queues.js:97:5)
    at async /Users/lero/Documents/My-data/BLOG/blog_service/node_modules/egg-development/app/middleware/egg_loader_trace.js:9:50
    at async xframe (/Users/lero/Documents/My-data/BLOG/blog_service/node_modules/egg-security/lib/middlewares/xframe.js:7:5)
    at async xssProtection (/Users/lero/Documents/My-data/BLOG/blog_service/node_modules/egg-security/lib/middlewares/xssProtection.js:7:5)
    at async nosniff (/Users/lero/Documents/My-data/BLOG/blog_service/node_modules/egg-security/lib/middlewares/nosniff.js:8:5)
    at async noopen (/Users/lero/Documents/My-data/BLOG/blog_service/node_modules/egg-security/lib/middlewares/noopen.js:8:5)
    at async session (/Users/lero/Documents/My-data/BLOG/blog_service/node_modules/koa-session/index.js:41:7)
    at async bodyParser (/Users/lero/Documents/My-data/BLOG/blog_service/node_modules/koa-bodyparser/index.js:95:5)
    at async /Users/lero/Documents/My-data/BLOG/blog_service/node_modules/koa-static-cache/index.js:41:56

pid: 85488
hostname: LEROLI-MB0

2020-12-15 21:27:55,515 ERROR 85488 [-/127.0.0.1/-/145ms GET /api/v1/blog/list] nodejs.TypeError: result is not iterable
    at HomeController.index (/Users/lero/Documents/My-data/BLOG/blog_service/app/controller/default/home.js:13:17)
    at processTicksAndRejections (internal/process/task_queues.js:97:5)
    at async /Users/lero/Documents/My-data/BLOG/blog_service/node_modules/egg-development/app/middleware/egg_loader_trace.js:9:50
    at async xframe (/Users/lero/Documents/My-data/BLOG/blog_service/node_modules/egg-security/lib/middlewares/xframe.js:7:5)
    at async xssProtection (/Users/lero/Documents/My-data/BLOG/blog_service/node_modules/egg-security/lib/middlewares/xssProtection.js:7:5)
    at async nosniff (/Users/lero/Documents/My-data/BLOG/blog_service/node_modules/egg-security/lib/middlewares/nosniff.js:8:5)
    at async noopen (/Users/lero/Documents/My-data/BLOG/blog_service/node_modules/egg-security/lib/middlewares/noopen.js:8:5)
    at async session (/Users/lero/Documents/My-data/BLOG/blog_service/node_modules/koa-session/index.js:41:7)
    at async bodyParser (/Users/lero/Documents/My-data/BLOG/blog_service/node_modules/koa-bodyparser/index.js:95:5)
    at async /Users/lero/Documents/My-data/BLOG/blog_service/node_modules/koa-static-cache/index.js:41:56

pid: 85488
hostname: LEROLI-MB0

2020-12-15 21:28:53,733 ERROR 85643 [-/127.0.0.1/-/148ms GET /api/v1/blog/list] nodejs.TypeError: Cannot read property 'push' of undefined
    at HomeController.index (/Users/lero/Documents/My-data/BLOG/blog_service/app/controller/default/home.js:10:10)
    at processTicksAndRejections (internal/process/task_queues.js:97:5)
    at async /Users/lero/Documents/My-data/BLOG/blog_service/node_modules/egg-development/app/middleware/egg_loader_trace.js:9:50
    at async xframe (/Users/lero/Documents/My-data/BLOG/blog_service/node_modules/egg-security/lib/middlewares/xframe.js:7:5)
    at async xssProtection (/Users/lero/Documents/My-data/BLOG/blog_service/node_modules/egg-security/lib/middlewares/xssProtection.js:7:5)
    at async nosniff (/Users/lero/Documents/My-data/BLOG/blog_service/node_modules/egg-security/lib/middlewares/nosniff.js:8:5)
    at async noopen (/Users/lero/Documents/My-data/BLOG/blog_service/node_modules/egg-security/lib/middlewares/noopen.js:8:5)
    at async session (/Users/lero/Documents/My-data/BLOG/blog_service/node_modules/koa-session/index.js:41:7)
    at async bodyParser (/Users/lero/Documents/My-data/BLOG/blog_service/node_modules/koa-bodyparser/index.js:95:5)
    at async /Users/lero/Documents/My-data/BLOG/blog_service/node_modules/koa-static-cache/index.js:41:56

pid: 85643
hostname: LEROLI-MB0

2020-12-16 14:47:20,513 ERROR 83277 [-/127.0.0.1/-/1ms GET /] nodejs.PROTOCOL_SEQUENCE_TIMEOUTError: Handshake inactivity timeout
    at Handshake.<anonymous> (/Users/lero/Documents/My-data/BLOG/blog_service/node_modules/mysql/lib/protocol/Protocol.js:160:17)
    at Handshake.emit (events.js:315:20)
    at Handshake._onTimeout (/Users/lero/Documents/My-data/BLOG/blog_service/node_modules/mysql/lib/protocol/sequences/Sequence.js:124:8)
    at Timer._onTimeout (/Users/lero/Documents/My-data/BLOG/blog_service/node_modules/mysql/lib/protocol/Timer.js:32:23)
    at listOnTimeout (internal/timers.js:549:17)
    at processTimers (internal/timers.js:492:7)
    --------------------
    at Protocol._enqueue (/Users/lero/Documents/My-data/BLOG/blog_service/node_modules/mysql/lib/protocol/Protocol.js:144:48)
    at Protocol.handshake (/Users/lero/Documents/My-data/BLOG/blog_service/node_modules/mysql/lib/protocol/Protocol.js:51:23)
    at PoolConnection.connect (/Users/lero/Documents/My-data/BLOG/blog_service/node_modules/mysql/lib/Connection.js:116:18)
    at Pool.getConnection (/Users/lero/Documents/My-data/BLOG/blog_service/node_modules/mysql/lib/Pool.js:48:16)
    at /Users/lero/Documents/My-data/BLOG/blog_service/node_modules/ali-rds/node_modules/pify/index.js:29:7
    at new Promise (<anonymous>)
    at Pool.<anonymous> (/Users/lero/Documents/My-data/BLOG/blog_service/node_modules/ali-rds/node_modules/pify/index.js:12:10)
    at Pool.ret [as getConnection] (/Users/lero/Documents/My-data/BLOG/blog_service/node_modules/ali-rds/node_modules/pify/index.js:56:34)
    at Pool.query (/Users/lero/Documents/My-data/BLOG/blog_service/node_modules/mysql/lib/Pool.js:202:8)
    at /Users/lero/Documents/My-data/BLOG/blog_service/node_modules/ali-rds/node_modules/pify/index.js:29:7
    sql: select now() as currentTime;
code: "PROTOCOL_SEQUENCE_TIMEOUT"
fatal: true
timeout: 10000
name: "PROTOCOL_SEQUENCE_TIMEOUTError"
pid: 83277
hostname: LEROLI-MB0

